Workbook

Sheet Calendario
A2: Atividade | B2: 2026 | G2: 2027 | S2: 2028
B3: AGO | C3: SET | D3: OUT | E3: NOV | F3: DEZ | G3: JAN | H3: FEV | I3: MAR | J3: ABR | K3: MAI | L3: JUN | M3: JUL | N3: AGO | O3: SET | P3: OUT | Q3: NOV | R3: DEZ | S3: JAN | T3: FEV | U3: MAR | V3: ABR | W3: MAI | X3: JUN | Y3: JUL
A4: PRAD CONJUNTO EÓLICO UMBURANAS - (ENGIE)
A5: Mobilização
A6: Plano de Trabalho
A7: Coleta de Solo
A8: Plantio - Sob demanda
A9: Manutenção Áreas de Restauração Florestal - PRAD
A10: Irrigação - Áreas de Restauração Florestal - PRAD
A11: Manutenção Sistema de Irrigação
A12: Monitoramento - Operacional
A13: Monitoramento - Ecológico
A14: Relatórios Trimestrais
A15: Relatórios Consolidados

Sheet Calendario Visual - Atividades
C1: CALENDARIO 2026 | I1: Enviado 06/08/2026
B2: Glebas | C2: Conjunto Eólico Umburanas | D2: Área PRAD | E2: Área (ha) | F2: Atuação | H2: AGOSTO | P2: SETEMBRO | X2: OUTUBRO | AF2: Atividade | AG2: Área | AH2: Início | AI2: Término Previsto | AJ2: Término Real | AK2: Prorrogação | AL2: Responsável | AM2: Status | AN2: % Concluído | AO2: Dias Restantes
B3: 1 | C3: Umburanas 25 | D3: Bota-fora 11 | E3: 1.1789 | F3: Reforma da gleba | H3: D | I3: S | J3: T | K3: Q | L3: Q | M3: S | N3: S | P3: D | Q3: S | R3: T | S3: Q | T3: Q | U3: S | V3: S | X3: D | Y3: S | Z3: T | AA3: Q | AB3: Q | AC3: S | AD3: S | AF3: Coleta de Solo | AG3: 50,26 ha | AH3: 46244 | AI3: 31/08/2026 | AL3: Equipe Campo | AM3: Em andamento | AN3: 0
B4: 2 | C4: Umburanas 01 | D4: Caixa de empréstimo 06 | E4: 1.5205 | N4: 1 | R4: 1 | S4: 2 | T4: 3 | U4: 4 | V4: 5 | AB4: 1 | AC4: 2 | AD4: 3 | AF4: Manutenção Canteiro Principal | AG4: 3,46 ha | AH4: 10/08/2026 | AI4: 31/08/2026 | AL4: Equipe Manutenção | AM4: Em andamento | AN4: 0
B5: 3 | C5: Umburanas 11 | D5: Bota fora 01 | E5: 0.2005 | F5: Manutenção média | H5: 2 | I5: 3 | J5: 4 | K5: 5 | L5: 6 | M5: 7 | N5: 8 | P5: 6 | Q5: 7 | R5: 8 | S5: 9 | T5: 10 | U5: 11 | V5: 12 | X5: 4 | Y5: 5 | Z5: 6 | AA5: 7 | AB5: 8 | AC5: 9 | AD5: 10 | AF5: Manutenção Sistema de Irrigação | AG5: 38 áreas | AH5: 10/08/2026 | AI5: 31/08/2026 | AL5: Equipe Irrigação | AM5: Não iniciado | AN5: 0
B6: 4 | C6: Umburanas 19 | D6: Bota-fora 02 | E6: 1.9474 | H6: 9 | I6: 10 | J6: 11 | K6: 12 | L6: 13 | M6: 14 | N6: 15 | P6: 13 | Q6: 14 | R6: 15 | S6: 16 | T6: 17 | U6: 18 | V6: 19 | X6: 11 | Y6: 12 | Z6: 13 | AA6: 14 | AB6: 15 | AC6: 16 | AD6: 17
B7: 5 | C7: Umburanas 15 | D7: Bota-fora 05 | E7: 1.9269 | H7: 16 | I7: 17 | J7: 18 | K7: 19 | L7: 20 | M7: 21 | N7: 22 | P7: 20 | Q7: 21 | R7: 22 | S7: 23 | T7: 24 | U7: 25 | V7: 26 | X7: 18 | Y7: 19 | Z7: 20 | AA7: 21 | AB7: 22 | AC7: 23 | AD7: 24
B8: 6 | C8: Umburanas 15 | D8: Bota-fora 07 | E8: 1.0423 | H8: 23 | I8: 24 | J8: 25 | K8: 26 | L8: 27 | M8: 28 | N8: 29 | P8: 27 | Q8: 28 | R8: 29 | S8: 30 | X8: 25 | Y8: 26 | Z8: 27 | AA8: 28 | AB8: 29 | AC8: 30 | AD8: 31 | AF8: DASHBOARD
B9: 7 | C9: Umburanas 02 | D9: Bota-fora 09 | E9: 0.6413 | H9: 30 | I9: 31 | AF9: Total Atividades
B10: 8 | C10: Umburanas 01 | D10: Bota-fora 10 | E10: 1.5492 | H10: NOVEMBRO | P10: DEZEMBRO | AF10: Concluídas
B11: 9 | C11: Umburanas 13 | D11: Bota-fora 13 | E11: 0.2808 | H11: D | I11: S | J11: T | K11: Q | L11: Q | M11: S | N11: S | P11: D | Q11: S | R11: T | S11: Q | T11: Q | U11: S | V11: S | AF11: Em andamento
B12: 10 | C12: Umburanas 17 e Umburanas 5 | D12: Bota-fora 15 | E12: 1.7881 | H12: 1 | I12: 2 | J12: 3 | K12: 4 | L12: 5 | M12: 6 | N12: 7 | R12: 1 | S12: 2 | T12: 3 | U12: 4 | V12: 5 | AF12: Não iniciado
B13: 11 | C13: Umburanas 17 | D13: Bota-fora 16 | E13: 0.5577 | H13: 8 | I13: 9 | J13: 10 | K13: 11 | L13: 12 | M13: 13 | N13: 14 | P13: 6 | Q13: 7 | R13: 8 | S13: 9 | T13: 10 | U13: 11 | V13: 12 | AF13: Progresso Geral
B14: 12 | C14: Umburanas 16 | D14: Bota-fora 18 | E14: 1.2913 | H14: 15 | I14: 16 | J14: 17 | K14: 18 | L14: 19 | M14: 20 | N14: 21 | P14: 13 | Q14: 14 | R14: 15 | S14: 16 | T14: 17 | U14: 18 | V14: 19
B15: 13 | C15: Umburanas 08 | D15: Bota-fora 20 | E15: 0.9706 | H15: 22 | I15: 23 | J15: 24 | K15: 25 | L15: 26 | M15: 27 | N15: 28 | P15: 20 | Q15: 21 | R15: 22 | S15: 23 | T15: 24 | U15: 25 | V15: 26
B16: 14 | C16: Umburanas 21 | D16: Bota-fora 21 | E16: 0.4258 | H16: 29 | I16: 30 | P16: 27 | Q16: 28 | R16: 29 | S16: 30 | T16: 31
B17: 15 | C17: Umburanas 18 | D17: Bota-fora 23 | E17: 1.3714
B18: 16 | C18: Umburanas 10 | D18: Bota-fora 26 | E18: 0.0475 | H18: LEGENDA
B19: 17 | C19: Umburanas 10 | D19: Bota-fora 27 | E19: 0.8429 | H19: Execução marcado em Amarelo na coluna B
B20: 18 | C20: Umburanas 10 | D20: Bota-fora 28 | E20: 0.2997 | H20: Conclusão marcado em Verde na coluna B
B21: 19 | C21: Umburanas 09 | D21: Bota-fora 29 | E21: 0.5502 | H21: Atividade Vermelho interrompida na Coluna B
B22: 20 | C22: Umburanas 01 e 03 | D22: Caixa de empréstimo 01 | E22: 2.0917
B23: 21 | C23: Umburanas 03 e 15 | D23: Caixa de empréstimo 02 | E23: 0.4833 | H23: Programação Quinzenal Nº 01 - Data: 06/08/2026
B24: 22 | C24: Umburanas 02 | D24: Caixa de empréstimo 05 | E24: 0.6519
B25: 23 | C25: Umburanas 17 | D25: Caixa de empréstimo 09 | E25: 1.41
B26: 24 | C26: Umburanas 05 | D26: Caixa de empréstimo 12 | E26: 1.5733
B27: 25 | C27: Umburanas 05 | D27: Canteiro de apoio 05 | E27: 0.6967
B28: 26 | C28: Umburanas 01 | D28: Canteiro principal | E28: 3.4615
B29: 27 | C29: Umburanas 13 | D29: Jazida Santo Anjo | E29: 3.6648
B30: 28 | C30: Umburanas 13 | D30: Jazida Santo Antonio | E30: 0.6258
B31: 29 | C31: Umburanas 17 | D31: Jazido Campo Alegre | E31: 4.6673
B32: 30 | C32: - | D32: Jazida do Meio | E32: 6.3908
B33: 31 | C33: Umburanas 02 | D33: Bota-fora 08 | E33: 1.2982 | F33: Manutenção básica
B34: 32 | C34: Umburanas 09 | D34: Bota-fora 24 | E34: 0.7486
B35: 33 | C35: Umburanas 19 | D35: Bota-fora 04 | E35: 0.6484 | F35: Áreas consolidadas
B36: 34 | C36: Umburanas 10 | D36: Caixa de empréstimo 14 | E36: 1.2756
B37: 35 | C37: Umburanas 23 | D37: Caixa de empréstimo 16 | E37: 0.3784
B38: 36 | C38: Umburanas 15 | D38: Canteiro de apoio 04 | E38: 0.3598
B39: 37 | C39: Umburanas 05 | D39: Bota-fora 22 | E39: 0.6392
B40: 38 | C40: Umburanas 05 | D40: Bota-fora 25 | E40: 0.7635
...

Sheet Planejamento
A1: PLANEJAMENTO E CONTROLE QUINZENAL
A3: ID | B3: Atividade | C3: Unidade | D3: Meta | E3: Início | F3: Término Previsto | G3: Término Real | H3: Nova Data | I3: Responsável | J3: Status | K3: % Concluído | L3: Executado | M3: Saldo | N3: Observações
A4: 1 | B4: Coleta de solo nas 38 áreas | C4: áreas | D4: 38 | E4: 46237 | F4: 46265 | G4: 46241 | I4: Equipe de Campo | J4: Concluído | K4: =IFERROR(MIN(L4/D4,1),0) -> 0.86842105 | L4: 33 | M4: =MAX(D4-L4,0) -> 5 | N4: Registrar áreas coletadas e hectares atendidos.
A5: 2 | B5: Avanço territorial consolidado | C5: ha | D5: 50.26 | E5: 46237 | F5: 46265 | I5: Equipe de Campo | J5: Em andamento | K5: =IFERROR(MIN(L5/D5,1),0) -> 0.068842021 | L5: 3.46 | M5: =MAX(D5-L5,0) -> 46.8 | N5: Hectares efetivamente atendidos no conjunto das 38 áreas.
A6: 3 | B6: Manutenção do canteiro principal | C6: ha | D6: 3.46 | E6: 46237 | F6: 46265 | G6: 46251 | I6: Equipe de Manutenção | J6: Concluído | K6: 1 | L6: 3.46 | M6: =MAX(D6-L6,0) -> 0 | N6: Coroamento, limpeza, reparos e organização operacional.
A7: 4 | B7: Manutenção do sistema de irrigação | C7: sistema | D7: 1 | E7: 46237 | F7: 46265 | I7: Equipe de Irrigação | J7: Em andamento | K7: 0 | L7: 0 | M7: =MAX(D7-L7,0) -> 1 | N7: Inspeção, testes, correções e substituições necessárias.

Sheet Cronograma 2026-2028
A1: CRONOGRAMA MACRO — PRAD CONJUNTO EÓLICO UMBURANAS (ENGIE) | AGO/2026 A JUL/2028
A2: ID | B2: Atividade | C2: Início | D2: Término Previsto | E2: Término Real | F2: Nova Data | G2: Status | H2: 46235 | I2: 46266 | J2: 46296 | K2: 46327 | L2: 46357 | M2: 46388 | N2: 46419 | O2: 46447 | P2: 46478 | Q2: 46508 | R2: 46539 | S2: 46569 | T2: 46600 | U2: 46631 | V2: 46661 | W2: 46692 | X2: 46722 | Y2: 46753 | Z2: 46784 | AA2: 46813 | AB2: 46844 | AC2: 46874 | AD2: 46905 | AE2: 46935
A3: 1 | B3: Mobilização | C3: 46239 | D3: 46239 | G3: Concluído | H3: =IF(OR($C3="",$D3=""),"",IF(AND(H$2<=EOMONTH(IF($F3<>"",$F3,$D3),0),EOMONTH(H$2,0)>=EOMONTH($C3,0)),IF($G3="Concluído",3,IF($G3="Atrasado",4,IF($G3="Prorrogado",5,IF($G3="Em andamento",2,1)))),"")) -> 3 | I3: =IF(OR($C3="",$D3=""),"",IF(AND(I$2<=EOMONTH(IF($F3<>"",$F3,$D3),0),EOMONTH(I$2,0)>=EOMONTH($C3,0)),IF($G3="Concluído",3,IF($G3="Atrasado",4,IF($G3="Prorrogado",5,IF($G3="Em andamento",2,1)))),"")) | J3: =IF(OR($C3="",$D3=""),"",IF(AND(J$2<=EOMONTH(IF($F3<>"",$F3,$D3),0),EOMONTH(J$2,0)>=EOMONTH($C3,0)),IF($G3="Concluído",3,IF($G3="Atrasado",4,IF($G3="Prorrogado",5,IF($G3="Em andamento",2,1)))),"")) | K3: =IF(OR($C3="",$D3=""),"",IF(AND(K$2<=EOMONTH(IF($F3<>"",$F3,$D3),0),EOMONTH(K$2,0)>=EOMONTH($C3,0)),IF($G3="Concluído",3,IF($G3="Atrasado",4,IF($G3="Prorrogado",5,IF($G3="Em andamento",2,1)))),"")) | L3: =IF(OR($C3="",$D3=""),"",IF(AND(L$2<=EOMONTH(IF($F3<>"",$F3,$D3),0),EOMONTH(L$2,0)>=EOMONTH($C3,0)),IF($G3="Concluído",3,IF($G3="Atrasado",4,IF($G3="Prorrogado",5,IF($G3="Em andamento",2,1)))),"")) | M3: =IF(OR($C3="",$D3=""),"",IF(AND(M$2<=EOMONTH(IF($F3<>"",$F3,$D3),0),EOMONTH(M$2,0)>=EOMONTH($C3,0)),IF($G3="Concluído",3,IF($G3="Atrasado",4,IF($G3="Prorrogado",5,IF($G3="Em andamento",2,1)))),"")) | N3: =IF(OR($C3="",$D3=""),"",IF(AND(N$2<=EOMONTH(IF($F3<>"",$F3,$D3),0),EOMONTH(N$2,0)>=EOMONTH($C3,0)),IF($G3="Concluído",3,IF($G3="Atrasado",4,IF($G3="Prorrogado",5,IF($G3="Em andamento",2,1)))),"")) | O3: =IF(OR($C3="",$D3=""),"",IF(AND(O$2<=EOMONTH(IF($F3<>"",$F3,$D3),0),EOMONTH(O$2,0)>=EOMONTH($C3,0)),IF($G3="Concluído",3,IF($G3="Atrasado",4,IF($G3="Prorrogado",5,IF($G3="Em andamento",2,1)))),"")) | ... AE3: =IF(OR($C3="",$D3=""),"",IF(AND(AE$2<=EOMONTH(IF($F3<>"",$F3,$D3),0),EOMONTH(AE$2,0)>=EOMONTH($C3,0)),IF($G3="Concluído",3,IF($G3="Atrasado",4,IF($G3="Prorrogado",5,IF($G3="Em andamento",2,1)))),""))
A4: 2 | B4: Plano de Trabalho | C4: 46223 | D4: 46237 | F4: 46252 | G4: Concluído | H4: =IF(OR($C4="",$D4=""),"",IF(AND(H$2<=EOMONTH(IF($F4<>"",$F4,$D4),0),EOMONTH(H$2,0)>=EOMONTH($C4,0)),IF($G4="Concluído",3,IF($G4="Atrasado",4,IF($G4="Prorrogado",5,IF($G4="Em andamento",2,1)))),"")) -> 3 | I4: =IF(OR($C4="",$D4=""),"",IF(AND(I$2<=EOMONTH(IF($F4<>"",$F4,$D4),0),EOMONTH(I$2,0)>=EOMONTH($C4,0)),IF($G4="Concluído",3,IF($G4="Atrasado",4,IF($G4="Prorrogado",5,IF($G4="Em andamento",2,1)))),"")) | J4: =IF(OR($C4="",$D4=""),"",IF(AND(J$2<=EOMONTH(IF($F4<>"",$F4,$D4),0),EOMONTH(J$2,0)>=EOMONTH($C4,0)),IF($G4="Concluído",3,IF($G4="Atrasado",4,IF($G4="Prorrogado",5,IF($G4="Em andamento",2,1)))),"")) | K4: =IF(OR($C4="",$D4=""),"",IF(AND(K$2<=EOMONTH(IF($F4<>"",$F4,$D4),0),EOMONTH(K$2,0)>=EOMONTH($C4,0)),IF($G4="Concluído",3,IF($G4="Atrasado",4,IF($G4="Prorrogado",5,IF($G4="Em andamento",2,1)))),"")) | L4: =IF(OR($C4="",$D4=""),"",IF(AND(L$2<=EOMONTH(IF($F4<>"",$F4,$D4),0),EOMONTH(L$2,0)>=EOMONTH($C4,0)),IF($G4="Concluído",3,IF($G4="Atrasado",4,IF($G4="Prorrogado",5,IF($G4="Em andamento",2,1)))),"")) | M4: =IF(OR($C4="",$D4=""),"",IF(AND(M$2<=EOMONTH(IF($F4<>"",$F4,$D4),0),EOMONTH(M$2,0)>=EOMONTH($C4,0)),IF($G4="Concluído",3,IF($G4="Atrasado",4,IF($G4="Prorrogado",5,IF($G4="Em andamento",2,1)))),"")) | N4: =IF(OR($C4="",$D4=""),"",IF(AND(N$2<=EOMONTH(IF($F4<>"",$F4,$D4),0),EOMONTH(N$2,0)>=EOMONTH($C4,0)),IF($G4="Concluído",3,IF($G4="Atrasado",4,IF($G4="Prorrogado",5,IF($G4="Em andamento",2,1)))),"")) | O4: =IF(OR($C4="",$D4=""),"",IF(AND(O$2<=EOMONTH(IF($F4<>"",$F4,$D4),0),EOMONTH(O$2,0)>=EOMONTH($C4,0)),IF($G4="Concluído",3,IF($G4="Atrasado",4,IF($G4="Prorrogado",5,IF($G4="Em andamento",2,1)))),"")) | ... AE4: =IF(OR($C4="",$D4=""),"",IF(AND(AE$2<=EOMONTH(IF($F4<>"",$F4,$D4),0),EOMONTH(AE$2,0)>=EOMONTH($C4,0)),IF($G4="Concluído",3,IF($G4="Atrasado",4,IF($G4="Prorrogado",5,IF($G4="Em andamento",2,1)))),""))
A5: 3 | B5: Coleta de Solo | C5: 46239 | D5: 46241 | G5: Concluído | H5: =IF(OR($C5="",$D5=""),"",IF(AND(H$2<=EOMONTH(IF($F5<>"",$F5,$D5),0),EOMONTH(H$2,0)>=EOMONTH($C5,0)),IF($G5="Concluído",3,IF($G5="Atrasado",4,IF($G5="Prorrogado",5,IF($G5="Em andamento",2,1)))),"")) -> 3 | I5: =IF(OR($C5="",$D5=""),"",IF(AND(I$2<=EOMONTH(IF($F5<>"",$F5,$D5),0),EOMONTH(I$2,0)>=EOMONTH($C5,0)),IF($G5="Concluído",3,IF($G5="Atrasado",4,IF($G5="Prorrogado",5,IF($G5="Em andamento",2,1)))),"")) | J5: =IF(OR($C5="",$D5=""),"",IF(AND(J$2<=EOMONTH(IF($F5<>"",$F5,$D5),0),EOMONTH(J$2,0)>=EOMONTH($C5,0)),IF($G5="Concluído",3,IF($G5="Atrasado",4,IF($G5="Prorrogado",5,IF($G5="Em andamento",2,1)))),"")) | K5: =IF(OR($C5="",$D5=""),"",IF(AND(K$2<=EOMONTH(IF($F5<>"",$F5,$D5),0),EOMONTH(K$2,0)>=EOMONTH($C5,0)),IF($G5="Concluído",3,IF($G5="Atrasado",4,IF($G5="Prorrogado",5,IF($G5="Em andamento",2,1)))),"")) | L5: =IF(OR($C5="",$D5=""),"",IF(AND(L$2<=EOMONTH(IF($F5<>"",$F5,$D5),0),EOMONTH(L$2,0)>=EOMONTH($C5,0)),IF($G5="Concluído",3,IF($G5="Atrasado",4,IF($G5="Prorrogado",5,IF($G5="Em andamento",2,1)))),"")) | M5: =IF(OR($C5="",$D5=""),"",IF(AND(M$2<=EOMONTH(IF($F5<>"",$F5,$D5),0),EOMONTH(M$2,0)>=EOMONTH($C5,0)),IF($G5="Concluído",3,IF($G5="Atrasado",4,IF($G5="Prorrogado",5,IF($G5="Em andamento",2,1)))),"")) | N5: =IF(OR($C5="",$D5=""),"",IF(AND(N$2<=EOMONTH(IF($F5<>"",$F5,$D5),0),EOMONTH(N$2,0)>=EOMONTH($C5,0)),IF($G5="Concluído",3,IF($G5="Atrasado",4,IF($G5="Prorrogado",5,IF($G5="Em andamento",2,1)))),"")) | O5: =IF(OR($C5="",$D5=""),"",IF(AND(O$2<=EOMONTH(IF($F5<>"",$F5,$D5),0),EOMONTH(O$2,0)>=EOMONTH($C5,0)),IF($G5="Concluído",3,IF($G5="Atrasado",4,IF($G5="Prorrogado",5,IF($G5="Em andamento",2,1)))),"")) | ... AE5: =IF(OR($C5="",$D5=""),"",IF(AND(AE$2<=EOMONTH(IF($F5<>"",$F5,$D5),0),EOMONTH(AE$2,0)>=EOMONTH($C5,0)),IF($G5="Concluído",3,IF($G5="Atrasado",4,IF($G5="Prorrogado",5,IF($G5="Em andamento",2,1)))),""))
A6: 4 | B6: Plantio - Sob demanda | G6: Não iniciado | H6: =IF(OR($C6="",$D6=""),"",IF(AND(H$2<=EOMONTH(IF($F6<>"",$F6,$D6),0),EOMONTH(H$2,0)>=EOMONTH($C6,0)),IF($G6="Concluído",3,IF($G6="Atrasado",4,IF($G6="Prorrogado",5,IF($G6="Em andamento",2,1)))),"")) | I6: =IF(OR($C6="",$D6=""),"",IF(AND(I$2<=EOMONTH(IF($F6<>"",$F6,$D6),0),EOMONTH(I$2,0)>=EOMONTH($C6,0)),IF($G6="Concluído",3,IF($G6="Atrasado",4,IF($G6="Prorrogado",5,IF($G6="Em andamento",2,1)))),"")) | J6: =IF(OR($C6="",$D6=""),"",IF(AND(J$2<=EOMONTH(IF($F6<>"",$F6,$D6),0),EOMONTH(J$2,0)>=EOMONTH($C6,0)),IF($G6="Concluído",3,IF($G6="Atrasado",4,IF($G6="Prorrogado",5,IF($G6="Em andamento",2,1)))),"")) | K6: =IF(OR($C6="",$D6=""),"",IF(AND(K$2<=EOMONTH(IF($F6<>"",$F6,$D6),0),EOMONTH(K$2,0)>=EOMONTH($C6,0)),IF($G6="Concluído",3,IF($G6="Atrasado",4,IF($G6="Prorrogado",5,IF($G6="Em andamento",2,1)))),"")) | L6: =IF(OR($C6="",$D6=""),"",IF(AND(L$2<=EOMONTH(IF($F6<>"",$F6,$D6),0),EOMONTH(L$2,0)>=EOMONTH($C6,0)),IF($G6="Concluído",3,IF($G6="Atrasado",4,IF($G6="Prorrogado",5,IF($G6="Em andamento",2,1)))),"")) | M6: =IF(OR($C6="",$D6=""),"",IF(AND(M$2<=EOMONTH(IF($F6<>"",$F6,$D6),0),EOMONTH(M$2,0)>=EOMONTH($C6,0)),IF($G6="Concluído",3,IF($G6="Atrasado",4,IF($G6="Prorrogado",5,IF($G6="Em andamento",2,1)))),"")) | N6: =IF(OR($C6="",$D6=""),"",IF(AND(N$2<=EOMONTH(IF($F6<>"",$F6,$D6),0),EOMONTH(N$2,0)>=EOMONTH($C6,0)),IF($G6="Concluído",3,IF($G6="Atrasado",4,IF($G6="Prorrogado",5,IF($G6="Em andamento",2,1)))),"")) | O6: =IF(OR($C6="",$D6=""),"",IF(AND(O$2<=EOMONTH(IF($F6<>"",$F6,$D6),0),EOMONTH(O$2,0)>=EOMONTH($C6,0)),IF($G6="Concluído",3,IF($G6="Atrasado",4,IF($G6="Prorrogado",5,IF($G6="Em andamento",2,1)))),"")) | ... AE6: =IF(OR($C6="",$D6=""),"",IF(AND(AE$2<=EOMONTH(IF($F6<>"",$F6,$D6),0),EOMONTH(AE$2,0)>=EOMONTH($C6,0)),IF($G6="Concluído",3,IF($G6="Atrasado",4,IF($G6="Prorrogado",5,IF($G6="Em andamento",2,1)))),""))
A7: 5 | B7: Manutenção Áreas de Restauração Florestal - PRAD | C7: 46244 | D7: 46251 | G7: Concluído | H7: =IF(OR($C7="",$D7=""),"",IF(AND(H$2<=EOMONTH(IF($F7<>"",$F7,$D7),0),EOMONTH(H$2,0)>=EOMONTH($C7,0)),IF($G7="Concluído",3,IF($G7="Atrasado",4,IF($G7="Prorrogado",5,IF($G7="Em andamento",2,1)))),"")) -> 3 | I7: =IF(OR($C7="",$D7=""),"",IF(AND(I$2<=EOMONTH(IF($F7<>"",$F7,$D7),0),EOMONTH(I$2,0)>=EOMONTH($C7,0)),IF($G7="Concluído",3,IF($G7="Atrasado",4,IF($G7="Prorrogado",5,IF($G7="Em andamento",2,1)))),"")) | J7: =IF(OR($C7="",$D7=""),"",IF(AND(J$2<=EOMONTH(IF($F7<>"",$F7,$D7),0),EOMONTH(J$2,0)>=EOMONTH($C7,0)),IF($G7="Concluído",3,IF($G7="Atrasado",4,IF($G7="Prorrogado",5,IF($G7="Em andamento",2,1)))),"")) | K7: =IF(OR($C7="",$D7=""),"",IF(AND(K$2<=EOMONTH(IF($F7<>"",$F7,$D7),0),EOMONTH(K$2,0)>=EOMONTH($C7,0)),IF($G7="Concluído",3,IF($G7="Atrasado",4,IF($G7="Prorrogado",5,IF($G7="Em andamento",2,1)))),"")) | L7: =IF(OR($C7="",$D7=""),"",IF(AND(L$2<=EOMONTH(IF($F7<>"",$F7,$D7),0),EOMONTH(L$2,0)>=EOMONTH($C7,0)),IF($G7="Concluído",3,IF($G7="Atrasado",4,IF($G7="Prorrogado",5,IF($G7="Em andamento",2,1)))),"")) | M7: =IF(OR($C7="",$D7=""),"",IF(AND(M$2<=EOMONTH(IF($F7<>"",$F7,$D7),0),EOMONTH(M$2,0)>=EOMONTH($C7,0)),IF($G7="Concluído",3,IF($G7="Atrasado",4,IF($G7="Prorrogado",5,IF($G7="Em andamento",2,1)))),"")) | N7: =IF(OR($C7="",$D7=""),"",IF(AND(N$2<=EOMONTH(IF($F7<>"",$F7,$D7),0),EOMONTH(N$2,0)>=EOMONTH($C7,0)),IF($G7="Concluído",3,IF($G7="Atrasado",4,IF($G7="Prorrogado",5,IF($G7="Em andamento",2,1)))),"")) | O7: =IF(OR($C7="",$D7=""),"",IF(AND(O$2<=EOMONTH(IF($F7<>"",$F7,$D7),0),EOMONTH(O$2,0)>=EOMONTH($C7,0)),IF($G7="Concluído",3,IF($G7="Atrasado",4,IF($G7="Prorrogado",5,IF($G7="Em andamento",2,1)))),"")) | ... AE7: =IF(OR($C7="",$D7=""),"",IF(AND(AE$2<=EOMONTH(IF($F7<>"",$F7,$D7),0),EOMONTH(AE$2,0)>=EOMONTH($C7,0)),IF($G7="Concluído",3,IF($G7="Atrasado",4,IF($G7="Prorrogado",5,IF($G7="Em andamento",2,1)))),""))
A8: 6 | B8: Irrigação - Áreas de Restauração Florestal - PRAD | G8: Não iniciado | H8: =IF(OR($C8="",$D8=""),"",IF(AND(H$2<=EOMONTH(IF($F8<>"",$F8,$D8),0),EOMONTH(H$2,0)>=EOMONTH($C8,0)),IF($G8="Concluído",3,IF($G8="Atrasado",4,IF($G8="Prorrogado",5,IF($G8="Em andamento",2,1)))),"")) | I8: =IF(OR($C8="",$D8=""),"",IF(AND(I$2<=EOMONTH(IF($F8<>"",$F8,$D8),0),EOMONTH(I$2,0)>=EOMONTH($C8,0)),IF($G8="Concluído",3,IF($G8="Atrasado",4,IF($G8="Prorrogado",5,IF($G8="Em andamento",2,1)))),"")) | J8: =IF(OR($C8="",$D8=""),"",IF(AND(J$2<=EOMONTH(IF($F8<>"",$F8,$D8),0),EOMONTH(J$2,0)>=EOMONTH($C8,0)),IF($G8="Concluído",3,IF($G8="Atrasado",4,IF($G8="Prorrogado",5,IF($G8="Em andamento",2,1)))),"")) | K8: =IF(OR($C8="",$D8=""),"",IF(AND(K$2<=EOMONTH(IF($F8<>"",$F8,$D8),0),EOMONTH(K$2,0)>=EOMONTH($C8,0)),IF($G8="Concluído",3,IF($G8="Atrasado",4,IF($G8="Prorrogado",5,IF($G8="Em andamento",2,1)))),"")) | L8: =IF(OR($C8="",$D8=""),"",IF(AND(L$2<=EOMONTH(IF($F8<>"",$F8,$D8),0),EOMONTH(L$2,0)>=EOMONTH($C8,0)),IF($G8="Concluído",3,IF($G8="Atrasado",4,IF($G8="Prorrogado",5,IF($G8="Em andamento",2,1)))),"")) | M8: =IF(OR($C8="",$D8=""),"",IF(AND(M$2<=EOMONTH(IF($F8<>"",$F8,$D8),0),EOMONTH(M$2,0)>=EOMONTH($C8,0)),IF($G8="Concluído",3,IF($G8="Atrasado",4,IF($G8="Prorrogado",5,IF($G8="Em andamento",2,1)))),"")) | N8: =IF(OR($C8="",$D8=""),"",IF(AND(N$2<=EOMONTH(IF($F8<>"",$F8,$D8),0),EOMONTH(N$2,0)>=EOMONTH($C8,0)),IF($G8="Concluído",3,IF($G8="Atrasado",4,IF($G8="Prorrogado",5,IF($G8="Em andamento",2,1)))),"")) | O8: =IF(OR($C8="",$D8=""),"",IF(AND(O$2<=EOMONTH(IF($F8<>"",$F8,$D8),0),EOMONTH(O$2,0)>=EOMONTH($C8,0)),IF($G8="Concluído",3,IF($G8="Atrasado",4,IF($G8="Prorrogado",5,IF($G8="Em andamento",2,1)))),"")) | ... AE8: =IF(OR($C8="",$D8=""),"",IF(AND(AE$2<=EOMONTH(IF($F8<>"",$F8,$D8),0),EOMONTH(AE$2,0)>=EOMONTH($C8,0)),IF($G8="Concluído",3,IF($G8="Atrasado",4,IF($G8="Prorrogado",5,IF($G8="Em andamento",2,1)))),""))
A9: 7 | B9: Manutenção Sistema de Irrigação | G9: Não iniciado | H9: =IF(OR($C9="",$D9=""),"",IF(AND(H$2<=EOMONTH(IF($F9<>"",$F9,$D9),0),EOMONTH(H$2,0)>=EOMONTH($C9,0)),IF($G9="Concluído",3,IF($G9="Atrasado",4,IF($G9="Prorrogado",5,IF($G9="Em andamento",2,1)))),"")) | I9: =IF(OR($C9="",$D9=""),"",IF(AND(I$2<=EOMONTH(IF($F9<>"",$F9,$D9),0),EOMONTH(I$2,0)>=EOMONTH($C9,0)),IF($G9="Concluído",3,IF($G9="Atrasado",4,IF($G9="Prorrogado",5,IF($G9="Em andamento",2,1)))),"")) | J9: =IF(OR($C9="",$D9=""),"",IF(AND(J$2<=EOMONTH(IF($F9<>"",$F9,$D9),0),EOMONTH(J$2,0)>=EOMONTH($C9,0)),IF($G9="Concluído",3,IF($G9="Atrasado",4,IF($G9="Prorrogado",5,IF($G9="Em andamento",2,1)))),"")) | K9: =IF(OR($C9="",$D9=""),"",IF(AND(K$2<=EOMONTH(IF($F9<>"",$F9,$D9),0),EOMONTH(K$2,0)>=EOMONTH($C9,0)),IF($G9="Concluído",3,IF($G9="Atrasado",4,IF($G9="Prorrogado",5,IF($G9="Em andamento",2,1)))),"")) | L9: =IF(OR($C9="",$D9=""),"",IF(AND(L$2<=EOMONTH(IF($F9<>"",$F9,$D9),0),EOMONTH(L$2,0)>=EOMONTH($C9,0)),IF($G9="Concluído",3,IF($G9="Atrasado",4,IF($G9="Prorrogado",5,IF($G9="Em andamento",2,1)))),"")) | M9: =IF(OR($C9="",$D9=""),"",IF(AND(M$2<=EOMONTH(IF($F9<>"",$F9,$D9),0),EOMONTH(M$2,0)>=EOMONTH($C9,0)),IF($G9="Concluído",3,IF($G9="Atrasado",4,IF($G9="Prorrogado",5,IF($G9="Em andamento",2,1)))),"")) | N9: =IF(OR($C9="",$D9=""),"",IF(AND(N$2<=EOMONTH(IF($F9<>"",$F9,$D9),0),EOMONTH(N$2,0)>=EOMONTH($C9,0)),IF($G9="Concluído",3,IF($G9="Atrasado",4,IF($G9="Prorrogado",5,IF($G9="Em andamento",2,1)))),"")) | O9: =IF(OR($C9="",$D9=""),"",IF(AND(O$2<=EOMONTH(IF($F9<>"",$F9,$D9),0),EOMONTH(O$2,0)>=EOMONTH($C9,0)),IF($G9="Concluído",3,IF($G9="Atrasado",4,IF($G9="Prorrogado",5,IF($G9="Em andamento",2,1)))),"")) | ... AE9: =IF(OR($C9="",$D9=""),"",IF(AND(AE$2<=EOMONTH(IF($F9<>"",$F9,$D9),0),EOMONTH(AE$2,0)>=EOMONTH($C9,0)),IF($G9="Concluído",3,IF($G9="Atrasado",4,IF($G9="Prorrogado",5,IF($G9="Em andamento",2,1)))),""))
A10: 8 | B10: Monitoramento - Operacional | G10: Não iniciado | H10: =IF(OR($C10="",$D10=""),"",IF(AND(H$2<=EOMONTH(IF($F10<>"",$F10,$D10),0),EOMONTH(H$2,0)>=EOMONTH($C10,0)),IF($G10="Concluído",3,IF($G10="Atrasado",4,IF($G10="Prorrogado",5,IF($G10="Em andamento",2,1)))),"")) | I10: =IF(OR($C10="",$D10=""),"",IF(AND(I$2<=EOMONTH(IF($F10<>"",$F10,$D10),0),EOMONTH(I$2,0)>=EOMONTH($C10,0)),IF($G10="Concluído",3,IF($G10="Atrasado",4,IF($G10="Prorrogado",5,IF($G10="Em andamento",2,1)))),"")) | J10: =IF(OR($C10="",$D10=""),"",IF(AND(J$2<=EOMONTH(IF($F10<>"",$F10,$D10),0),EOMONTH(J$2,0)>=EOMONTH($C10,0)),IF($G10="Concluído",3,IF($G10="Atrasado",4,IF($G10="Prorrogado",5,IF($G10="Em andamento",2,1)))),"")) | K10: =IF(OR($C10="",$D10=""),"",IF(AND(K$2<=EOMONTH(IF($F10<>"",$F10,$D10),0),EOMONTH(K$2,0)>=EOMONTH($C10,0)),IF($G10="Concluído",3,IF($G10="Atrasado",4,IF($G10="Prorrogado",5,IF($G10="Em andamento",2,1)))),"")) | L10: =IF(OR($C10="",$D10=""),"",IF(AND(L$2<=EOMONTH(IF($F10<>"",$F10,$D10),0),EOMONTH(L$2,0)>=EOMONTH($C10,0)),IF($G10="Concluído",3,IF($G10="Atrasado",4,IF($G10="Prorrogado",5,IF($G10="Em andamento",2,1)))),"")) | M10: =IF(OR($C10="",$D10=""),"",IF(AND(M$2<=EOMONTH(IF($F10<>"",$F10,$D10),0),EOMONTH(M$2,0)>=EOMONTH($C10,0)),IF($G10="Concluído",3,IF($G10="Atrasado",4,IF($G10="Prorrogado",5,IF($G10="Em andamento",2,1)))),"")) | N10: =IF(OR($C10="",$D10=""),"",IF(AND(N$2<=EOMONTH(IF($F10<>"",$F10,$D10),0),EOMONTH(N$2,0)>=EOMONTH($C10,0)),IF($G10="Concluído",3,IF($G10="Atrasado",4,IF($G10="Prorrogado",5,IF($G10="Em andamento",2,1)))),"")) | O10: =IF(OR($C10="",$D10=""),"",IF(AND(O$2<=EOMONTH(IF($F10<>"",$F10,$D10),0),EOMONTH(O$2,0)>=EOMONTH($C10,0)),IF($G10="Concluído",3,IF($G10="Atrasado",4,IF($G10="Prorrogado",5,IF($G10="Em andamento",2,1)))),"")) | ... AE10: =IF(OR($C10="",$D10=""),"",IF(AND(AE$2<=EOMONTH(IF($F10<>"",$F10,$D10),0),EOMONTH(AE$2,0)>=EOMONTH($C10,0)),IF($G10="Concluído",3,IF($G10="Atrasado",4,IF($G10="Prorrogado",5,IF($G10="Em andamento",2,1)))),""))
A11: 9 | B11: Monitoramento - Ecológico | G11: Não iniciado | H11: =IF(OR($C11="",$D11=""),"",IF(AND(H$2<=EOMONTH(IF($F11<>"",$F11,$D11),0),EOMONTH(H$2,0)>=EOMONTH($C11,0)),IF($G11="Concluído",3,IF($G11="Atrasado",4,IF($G11="Prorrogado",5,IF($G11="Em andamento",2,1)))),"")) | I11: =IF(OR($C11="",$D11=""),"",IF(AND(I$2<=EOMONTH(IF($F11<>"",$F11,$D11),0),EOMONTH(I$2,0)>=EOMONTH($C11,0)),IF($G11="Concluído",3,IF($G11="Atrasado",4,IF($G11="Prorrogado",5,IF($G11="Em andamento",2,1)))),"")) | J11: =IF(OR($C11="",$D11=""),"",IF(AND(J$2<=EOMONTH(IF($F11<>"",$F11,$D11),0),EOMONTH(J$2,0)>=EOMONTH($C11,0)),IF($G11="Concluído",3,IF($G11="Atrasado",4,IF($G11="Prorrogado",5,IF($G11="Em andamento",2,1)))),"")) | K11: =IF(OR($C11="",$D11=""),"",IF(AND(K$2<=EOMONTH(IF($F11<>"",$F11,$D11),0),EOMONTH(K$2,0)>=EOMONTH($C11,0)),IF($G11="Concluído",3,IF($G11="Atrasado",4,IF($G11="Prorrogado",5,IF($G11="Em andamento",2,1)))),"")) | L11: =IF(OR($C11="",$D11=""),"",IF(AND(L$2<=EOMONTH(IF($F11<>"",$F11,$D11),0),EOMONTH(L$2,0)>=EOMONTH($C11,0)),IF($G11="Concluído",3,IF($G11="Atrasado",4,IF($G11="Prorrogado",5,IF($G11="Em andamento",2,1)))),"")) | M11: =IF(OR($C11="",$D11=""),"",IF(AND(M$2<=EOMONTH(IF($F11<>"",$F11,$D11),0),EOMONTH(M$2,0)>=EOMONTH($C11,0)),IF($G11="Concluído",3,IF($G11="Atrasado",4,IF($G11="Prorrogado",5,IF($G11="Em andamento",2,1)))),"")) | N11: =IF(OR($C11="",$D11=""),"",IF(AND(N$2<=EOMONTH(IF($F11<>"",$F11,$D11),0),EOMONTH(N$2,0)>=EOMONTH($C11,0)),IF($G11="Concluído",3,IF($G11="Atrasado",4,IF($G11="Prorrogado",5,IF($G11="Em andamento",2,1)))),"")) | O11: =IF(OR($C11="",$D11=""),"",IF(AND(O$2<=EOMONTH(IF($F11<>"",$F11,$D11),0),EOMONTH(O$2,0)>=EOMONTH($C11,0)),IF($G11="Concluído",3,IF($G11="Atrasado",4,IF($G11="Prorrogado",5,IF($G11="Em andamento",2,1)))),"")) | ... AE11: =IF(OR($C11="",$D11=""),"",IF(AND(AE$2<=EOMONTH(IF($F11<>"",$F11,$D11),0),EOMONTH(AE$2,0)>=EOMONTH($C11,0)),IF($G11="Concluído",3,IF($G11="Atrasado",4,IF($G11="Prorrogado",5,IF($G11="Em andamento",2,1)))),""))
A12: 10 | B12: Relatórios Trimestrais | G12: Não iniciado | H12: =IF(OR($C12="",$D12=""),"",IF(AND(H$2<=EOMONTH(IF($F12<>"",$F12,$D12),0),EOMONTH(H$2,0)>=EOMONTH($C12,0)),IF($G12="Concluído",3,IF($G12="Atrasado",4,IF($G12="Prorrogado",5,IF($G12="Em andamento",2,1)))),"")) | I12: =IF(OR($C12="",$D12=""),"",IF(AND(I$2<=EOMONTH(IF($F12<>"",$F12,$D12),0),EOMONTH(I$2,0)>=EOMONTH($C12,0)),IF($G12="Concluído",3,IF($G12="Atrasado",4,IF($G12="Prorrogado",5,IF($G12="Em andamento",2,1)))),"")) | J12: =IF(OR($C12="",$D12=""),"",IF(AND(J$2<=EOMONTH(IF($F12<>"",$F12,$D12),0),EOMONTH(J$2,0)>=EOMONTH($C12,0)),IF($G12="Concluído",3,IF($G12="Atrasado",4,IF($G12="Prorrogado",5,IF($G12="Em andamento",2,1)))),"")) | K12: =IF(OR($C12="",$D12=""),"",IF(AND(K$2<=EOMONTH(IF($F12<>"",$F12,$D12),0),EOMONTH(K$2,0)>=EOMONTH($C12,0)),IF($G12="Concluído",3,IF($G12="Atrasado",4,IF($G12="Prorrogado",5,IF($G12="Em andamento",2,1)))),"")) | L12: =IF(OR($C12="",$D12=""),"",IF(AND(L$2<=EOMONTH(IF($F12<>"",$F12,$D12),0),EOMONTH(L$2,0)>=EOMONTH($C12,0)),IF($G12="Concluído",3,IF($G12="Atrasado",4,IF($G12="Prorrogado",5,IF($G12="Em andamento",2,1)))),"")) | M12: =IF(OR($C12="",$D12=""),"",IF(AND(M$2<=EOMONTH(IF($F12<>"",$F12,$D12),0),EOMONTH(M$2,0)>=EOMONTH($C12,0)),IF($G12="Concluído",3,IF($G12="Atrasado",4,IF($G12="Prorrogado",5,IF($G12="Em andamento",2,1)))),"")) | N12: =IF(OR($C12="",$D12=""),"",IF(AND(N$2<=EOMONTH(IF($F12<>"",$F12,$D12),0),EOMONTH(N$2,0)>=EOMONTH($C12,0)),IF($G12="Concluído",3,IF($G12="Atrasado",4,IF($G12="Prorrogado",5,IF($G12="Em andamento",2,1)))),"")) | O12: =IF(OR($C12="",$D12=""),"",IF(AND(O$2<=EOMONTH(IF($F12<>"",$F12,$D12),0),EOMONTH(O$2,0)>=EOMONTH($C12,0)),IF($G12="Concluído",3,IF($G12="Atrasado",4,IF($G12="Prorrogado",5,IF($G12="Em andamento",2,1)))),"")) | ... AE12: =IF(OR($C12="",$D12=""),"",IF(AND(AE$2<=EOMONTH(IF($F12<>"",$F12,$D12),0),EOMONTH(AE$2,0)>=EOMONTH($C12,0)),IF($G12="Concluído",3,IF($G12="Atrasado",4,IF($G12="Prorrogado",5,IF($G12="Em andamento",2,1)))),""))
A13: 11 | B13: Relatórios Consolidados | G13: Não iniciado | H13: =IF(OR($C13="",$D13=""),"",IF(AND(H$2<=EOMONTH(IF($F13<>"",$F13,$D13),0),EOMONTH(H$2,0)>=EOMONTH($C13,0)),IF($G13="Concluído",3,IF($G13="Atrasado",4,IF($G13="Prorrogado",5,IF($G13="Em andamento",2,1)))),"")) | I13: =IF(OR($C13="",$D13=""),"",IF(AND(I$2<=EOMONTH(IF($F13<>"",$F13,$D13),0),EOMONTH(I$2,0)>=EOMONTH($C13,0)),IF($G13="Concluído",3,IF($G13="Atrasado",4,IF($G13="Prorrogado",5,IF($G13="Em andamento",2,1)))),"")) | J13: =IF(OR($C13="",$D13=""),"",IF(AND(J$2<=EOMONTH(IF($F13<>"",$F13,$D13),0),EOMONTH(J$2,0)>=EOMONTH($C13,0)),IF($G13="Concluído",3,IF($G13="Atrasado",4,IF($G13="Prorrogado",5,IF($G13="Em andamento",2,1)))),"")) | K13: =IF(OR($C13="",$D13=""),"",IF(AND(K$2<=EOMONTH(IF($F13<>"",$F13,$D13),0),EOMONTH(K$2,0)>=EOMONTH($C13,0)),IF($G13="Concluído",3,IF($G13="Atrasado",4,IF($G13="Prorrogado",5,IF($G13="Em andamento",2,1)))),"")) | L13: =IF(OR($C13="",$D13=""),"",IF(AND(L$2<=EOMONTH(IF($F13<>"",$F13,$D13),0),EOMONTH(L$2,0)>=EOMONTH($C13,0)),IF($G13="Concluído",3,IF($G13="Atrasado",4,IF($G13="Prorrogado",5,IF($G13="Em andamento",2,1)))),"")) | M13: =IF(OR($C13="",$D13=""),"",IF(AND(M$2<=EOMONTH(IF($F13<>"",$F13,$D13),0),EOMONTH(M$2,0)>=EOMONTH($C13,0)),IF($G13="Concluído",3,IF($G13="Atrasado",4,IF($G13="Prorrogado",5,IF($G13="Em andamento",2,1)))),"")) | N13: =IF(OR($C13="",$D13=""),"",IF(AND(N$2<=EOMONTH(IF($F13<>"",$F13,$D13),0),EOMONTH(N$2,0)>=EOMONTH($C13,0)),IF($G13="Concluído",3,IF($G13="Atrasado",4,IF($G13="Prorrogado",5,IF($G13="Em andamento",2,1)))),"")) | O13: =IF(OR($C13="",$D13=""),"",IF(AND(O$2<=EOMONTH(IF($F13<>"",$F13,$D13),0),EOMONTH(O$2,0)>=EOMONTH($C13,0)),IF($G13="Concluído",3,IF($G13="Atrasado",4,IF($G13="Prorrogado",5,IF($G13="Em andamento",2,1)))),"")) | ... AE13: =IF(OR($C13="",$D13=""),"",IF(AND(AE$2<=EOMONTH(IF($F13<>"",$F13,$D13),0),EOMONTH(AE$2,0)>=EOMONTH($C13,0)),IF($G13="Concluído",3,IF($G13="Atrasado",4,IF($G13="Prorrogado",5,IF($G13="Em andamento",2,1)))),""))
A14: 12 | B14: Reunião Quinzenal | C14: 46254 | D14: 46254 | G14: Em andamento | H14: =IF(OR($C14="",$D14=""),"",IF(AND(H$2<=EOMONTH(IF($F14<>"",$F14,$D14),0),EOMONTH(H$2,0)>=EOMONTH($C14,0)),IF($G14="Concluído",3,IF($G14="Atrasado",4,IF($G14="Prorrogado",5,IF($G14="Em andamento",2,1)))),"")) -> 2
A15: Legenda | B15: Planejado | C15: Em andamento | D15: Concluído | E15: Atrasado | F15: Prorrogado

Sheet Controle Integrado
A1: CONTROLE INTEGRADO DAS ÁREAS E ATIVIDADES — PREENCHIMENTO ÚNICO
A3: Nº | B3: Conjunto Eólico | C3: Área PRAD | D3: Área (ha) | E3: Atuação | F3: Coleta de Solo | G3: Data Coleta | H3: Manutenção PRAD | I3: Data Manutenção | J3: Irrigação | K3: Data Irrigação | L3: Monitoramento Operacional | M3: Monitoramento Ecológico | N3: Responsável | O3: Status Geral | P3: % Geral | Q3: Início | R3: Término Previsto | S3: Término Real | T3: Nova Data | U3: Dias Restantes | V3: Observações
A4: 1 | B4: Umburanas 25 | C4: Bota-fora 11 | D4: 1.18 | E4: Reforma da gleba | F4: Suspenso | H4: Não iniciado | J4: Não iniciado | L4: Não iniciado | M4: Não iniciado | N4: Equipe de Campo | O4: =IF(P4=0,"Não iniciado",IF(P4=1,"Concluído",IF(AND(TODAY()>IF(T4<>"",T4,R4),P4<1),"Atrasado","Em andamento"))) -> Não iniciado | P4: =IFERROR((COUNTIF(F4,"Concluído")+COUNTIF(H4,"Concluído")+COUNTIF(J4,"Concluído")+COUNTIF(L4,"Concluído")+COUNTIF(M4,"Concluído"))/5,0) -> 0 | Q4: 46239 | R4: 46265 | U4: =MAX(IF(T4<>"",T4,R4)-TODAY(),0) -> 12 | V4: Questões Fundiarias
A5: 2 | B5: Umburanas 01 | C5: Caixa de empréstimo 06 | D5: 1.52 | F5: Concluído | G5: 46241 | H5: Não iniciado | J5: Não iniciado | L5: Não iniciado | M5: Não iniciado | N5: Equipe de Campo | O5: =IF(P5=0,"Não iniciado",IF(P5=1,"Concluído",IF(AND(TODAY()>IF(T5<>"",T5,R5),P5<1),"Atrasado","Em andamento"))) -> Em andamento | P5: =IFERROR((COUNTIF(F5,"Concluído")+COUNTIF(H5,"Concluído")+COUNTIF(J5,"Concluído")+COUNTIF(L5,"Concluído")+COUNTIF(M5,"Concluído"))/5,0) -> 0.2 | Q5: 46239 | R5: 46265 | U5: =MAX(IF(T5<>"",T5,R5)-TODAY(),0) -> 12
A6: 3 | B6: Umburanas 11 | C6: Bota fora 01 | D6: 0.2 | E6: Manutenção média | F6: Concluído | G6: 46241 | H6: Não iniciado | J6: Não iniciado | L6: Não iniciado | M6: Não iniciado | N6: Equipe de Campo | O6: =IF(P6=0,"Não iniciado",IF(P6=1,"Concluído",IF(AND(TODAY()>IF(T6<>"",T6,R6),P6<1),"Atrasado","Em andamento"))) -> Em andamento | P6: =IFERROR((COUNTIF(F6,"Concluído")+COUNTIF(H6,"Concluído")+COUNTIF(J6,"Concluído")+COUNTIF(L6,"Concluído")+COUNTIF(M6,"Concluído"))/5,0) -> 0.2 | Q6: 46239 | R6: 46265 | U6: =MAX(IF(T6<>"",T6,R6)-TODAY(),0) -> 12
A7: 4 | B7: Umburanas 19 | C7: Bota-fora 02 | D7: 1.95 | F7: Concluído | G7: 46241 | H7: Não iniciado | J7: Não iniciado | L7: Não iniciado | M7: Não iniciado | N7: Equipe de Campo | O7: =IF(P7=0,"Não iniciado",IF(P7=1,"Concluído",IF(AND(TODAY()>IF(T7<>"",T7,R7),P7<1),"Atrasado","Em andamento"))) -> Em andamento | P7: =IFERROR((COUNTIF(F7,"Concluído")+COUNTIF(H7,"Concluído")+COUNTIF(J7,"Concluído")+COUNTIF(L7,"Concluído")+COUNTIF(M7,"Concluído"))/5,0) -> 0.2 | Q7: 46239 | R7: 46265 | U7: =MAX(IF(T7<>"",T7,R7)-TODAY(),0) -> 12
A8: 5 | B8: Umburanas 15 | C8: Bota-fora 05 | D8: 1.93 | F8: Concluído | G8: 46241 | H8: Não iniciado | J8: Não iniciado | L8: Não iniciado | M8: Não iniciado | N8: Equipe de Campo | O8: =IF(P8=0,"Não iniciado",IF(P8=1,"Concluído",IF(AND(TODAY()>IF(T8<>"",T8,R8),P8<1),"Atrasado","Em andamento"))) -> Em andamento | P8: =IFERROR((COUNTIF(F8,"Concluído")+COUNTIF(H8,"Concluído")+COUNTIF(J8,"Concluído")+COUNTIF(L8,"Concluído")+COUNTIF(M8,"Concluído"))/5,0) -> 0.2 | Q8: 46239 | R8: 46265 | U8: =MAX(IF(T8<>"",T8,R8)-TODAY(),0) -> 12
A9: 6 | B9: Umburanas 15 | C9: Bota-fora 07 | D9: 1.04 | F9: Concluído | G9: 46241 | H9: Não iniciado | J9: Não iniciado | L9: Não iniciado | M9: Não iniciado | N9: Equipe de Campo | O9: =IF(P9=0,"Não iniciado",IF(P9=1,"Concluído",IF(AND(TODAY()>IF(T9<>"",T9,R9),P9<1),"Atrasado","Em andamento"))) -> Em andamento | P9: =IFERROR((COUNTIF(F9,"Concluído")+COUNTIF(H9,"Concluído")+COUNTIF(J9,"Concluído")+COUNTIF(L9,"Concluído")+COUNTIF(M9,"Concluído"))/5,0) -> 0.2 | Q9: 46239 | R9: 46265 | U9: =MAX(IF(T9<>"",T9,R9)-TODAY(),0) -> 12
A10: 7 | B10: Umburanas 02 | C10: Bota-fora 09 | D10: 0.64 | F10: Concluído | G10: 46241 | H10: Não iniciado | J10: Não iniciado | L10: Não iniciado | M10: Não iniciado | N10: Equipe de Campo | O10: =IF(P10=0,"Não iniciado",IF(P10=1,"Concluído",IF(AND(TODAY()>IF(T10<>"",T10,R10),P10<1),"Atrasado","Em andamento"))) -> Em andamento | P10: =IFERROR((COUNTIF(F10,"Concluído")+COUNTIF(H10,"Concluído")+COUNTIF(J10,"Concluído")+COUNTIF(L10,"Concluído")+COUNTIF(M10,"Concluído"))/5,0) -> 0.2 | Q10: 46239 | R10: 46265 | U10: =MAX(IF(T10<>"",T10,R10)-TODAY(),0) -> 12
A11: 8 | B11: Umburanas 01 | C11: Bota-fora 10 | D11: 1.55 | F11: Concluído | G11: 46241 | H11: Não iniciado | J11: Não iniciado | L11: Não iniciado | M11: Não iniciado | N11: Equipe de Campo | O11: =IF(P11=0,"Não iniciado",IF(P11=1,"Concluído",IF(AND(TODAY()>IF(T11<>"",T11,R11),P11<1),"Atrasado","Em andamento"))) -> Em andamento | P11: =IFERROR((COUNTIF(F11,"Concluído")+COUNTIF(H11,"Concluído")+COUNTIF(J11,"Concluído")+COUNTIF(L11,"Concluído")+COUNTIF(M11,"Concluído"))/5,0) -> 0.2 | Q11: 46239 | R11: 46265 | U11: =MAX(IF(T11<>"",T11,R11)-TODAY(),0) -> 12
A12: 9 | B12: Umburanas 13 | C12: Bota-fora 13 | D12: 0.28 | F12: Concluído | G12: 46241 | H12: Não iniciado | J12: Não iniciado | L12: Não iniciado | M12: Não iniciado | N12: Equipe de Campo | O12: =IF(P12=0,"Não iniciado",IF(P12=1,"Concluído",IF(AND(TODAY()>IF(T12<>"",T12,R12),P12<1),"Atrasado","Em andamento"))) -> Em andamento | P12: =IFERROR((COUNTIF(F12,"Concluído")+COUNTIF(H12,"Concluído")+COUNTIF(J12,"Concluído")+COUNTIF(L12,"Concluído")+COUNTIF(M12,"Concluído"))/5,0) -> 0.2 | Q12: 46239 | R12: 46265 | U12: =MAX(IF(T12<>"",T12,R12)-TODAY(),0) -> 12
A13: 10 | B13: Umburanas 17 e Umburanas 5 | C13: Bota-fora 15 | D13: 1.79 | F13: Concluído | G13: 46241 | H13: Não iniciado | J13: Não iniciado | L13: Não iniciado | M13: Não iniciado | N13: Equipe de Campo | O13: =IF(P13=0,"Não iniciado",IF(P13=1,"Concluído",IF(AND(TODAY()>IF(T13<>"",T13,R13),P13<1),"Atrasado","Em andamento"))) -> Em andamento | P13: =IFERROR((COUNTIF(F13,"Concluído")+COUNTIF(H13,"Concluído")+COUNTIF(J13,"Concluído")+COUNTIF(L13,"Concluído")+COUNTIF(M13,"Concluído"))/5,0) -> 0.2 | Q13: 46239 | R13: 46265 | U13: =MAX(IF(T13<>"",T13,R13)-TODAY(),0) -> 12
A14: 11 | B14: Umburanas 17 | C14: Bota-fora 16 | D14: 0.56 | F14: Concluído | G14: 46241 | H14: Não iniciado | J14: Não iniciado | L14: Não iniciado | M14: Não iniciado | N14: Equipe de Campo | O14: =IF(P14=0,"Não iniciado",IF(P14=1,"Concluído",IF(AND(TODAY()>IF(T14<>"",T14,R14),P14<1),"Atrasado","Em andamento"))) -> Em andamento | P14: =IFERROR((COUNTIF(F14,"Concluído")+COUNTIF(H14,"Concluído")+COUNTIF(J14,"Concluído")+COUNTIF(L14,"Concluído")+COUNTIF(M14,"Concluído"))/5,0) -> 0.2 | Q14: 46239 | R14: 46265 | U14: =MAX(IF(T14<>"",T14,R14)-TODAY(),0) -> 12
A15: 12 | B15: Umburanas 16 | C15: Bota-fora 18 | D15: 1.29 | F15: Concluído | G15: 46241 | H15: Não iniciado | J15: Não iniciado | L15: Não iniciado | M15: Não iniciado | N15: Equipe de Campo | O15: =IF(P15=0,"Não iniciado",IF(P15=1,"Concluído",IF(AND(TODAY()>IF(T15<>"",T15,R15),P15<1),"Atrasado","Em andamento"))) -> Em andamento | P15: =IFERROR((COUNTIF(F15,"Concluído")+COUNTIF(H15,"Concluído")+COUNTIF(J15,"Concluído")+COUNTIF(L15,"Concluído")+COUNTIF(M15,"Concluído"))/5,0) -> 0.2 | Q15: 46239 | R15: 46265 | U15: =MAX(IF(T15<>"",T15,R15)-TODAY(),0) -> 12
A16: 13 | B16: Umburanas 08 | C16: Bota-fora 20 | D16: 0.97 | F16: Concluído | G16: 46241 | H16: Não iniciado | J16: Não iniciado | L16: Não iniciado | M16: Não iniciado | N16: Equipe de Campo | O16: =IF(P16=0,"Não iniciado",IF(P16=1,"Concluído",IF(AND(TODAY()>IF(T16<>"",T16,R16),P16<1),"Atrasado","Em andamento"))) -> Em andamento | P16: =IFERROR((COUNTIF(F16,"Concluído")+COUNTIF(H16,"Concluído")+COUNTIF(J16,"Concluído")+COUNTIF(L16,"Concluído")+COUNTIF(M16,"Concluído"))/5,0) -> 0.2 | Q16: 46239 | R16: 46265 | U16: =MAX(IF(T16<>"",T16,R16)-TODAY(),0) -> 12
A17: 14 | B17: Umburanas 21 | C17: Bota-fora 21 | D17: 0.43 | F17: Concluído | G17: 46241 | H17: Não iniciado | J17: Não iniciado | L17: Não iniciado | M17: Não iniciado | N17: Equipe de Campo | O17: =IF(P17=0,"Não iniciado",IF(P17=1,"Concluído",IF(AND(TODAY()>IF(T17<>"",T17,R17),P17<1),"Atrasado","Em andamento"))) -> Em andamento | P17: =IFERROR((COUNTIF(F17,"Concluído")+COUNTIF(H17,"Concluído")+COUNTIF(J17,"Concluído")+COUNTIF(L17,"Concluído")+COUNTIF(M17,"Concluído"))/5,0) -> 0.2 | Q17: 46239 | R17: 46265 | U17: =MAX(IF(T17<>"",T17,R17)-TODAY(),0) -> 12
A18: 15 | B18: Umburanas 18 | C18: Bota-fora 23 | D18: 1.37 | F18: Concluído | G18: 46241 | H18: Não iniciado | J18: Não iniciado | L18: Não iniciado | M18: Não iniciado | N18: Equipe de Campo | O18: =IF(P18=0,"Não iniciado",IF(P18=1,"Concluído",IF(AND(TODAY()>IF(T18<>"",T18,R18),P18<1),"Atrasado","Em andamento"))) -> Em andamento | P18: =IFERROR((COUNTIF(F18,"Concluído")+COUNTIF(H18,"Concluído")+COUNTIF(J18,"Concluído")+COUNTIF(L18,"Concluído")+COUNTIF(M18,"Concluído"))/5,0) -> 0.2 | Q18: 46239 | R18: 46265 | U18: =MAX(IF(T18<>"",T18,R18)-TODAY(),0) -> 12
... A28: 25 | B28: Umburanas 05 | C28: Canteiro de apoio 05 | D28: 0.7 | F28: Concluído | G28: 46241 | H28: Não iniciado | J28: Não iniciado | L28: Não iniciado | M28: Não iniciado | N28: Equipe de Campo | O28: =IF(P28=0,"Não iniciado",IF(P28=1,"Concluído",IF(AND(TODAY()>IF(T28<>"",T28,R28),P28<1),"Atrasado","Em andamento"))) -> Em andamento | P28: =IFERROR((COUNTIF(F28,"Concluído")+COUNTIF(H28,"Concluído")+COUNTIF(J28,"Concluído")+COUNTIF(L28,"Concluído")+COUNTIF(M28,"Concluído"))/5,0) -> 0.2 | Q28: 46239 | R28: 46265 | U28: =MAX(IF(T28<>"",T28,R28)-TODAY(),0) -> 12
A29: 26 | B29: Umburanas 01 | C29: Canteiro principal | D29: 3.46 | F29: Concluído | G29: 46241 | H29: Concluído | I29: 46251 | J29: Não iniciado | L29: Não iniciado | M29: Não iniciado | N29: Equipe de Campo | O29: =IF(P29=0,"Não iniciado",IF(P29=1,"Concluído",IF(AND(TODAY()>IF(T29<>"",T29,R29),P29<1),"Atrasado","Em andamento"))) -> Em andamento | P29: =IFERROR((COUNTIF(F29,"Concluído")+COUNTIF(H29,"Concluído")+COUNTIF(J29,"Concluído")+COUNTIF(L29,"Concluído")+COUNTIF(M29,"Concluído"))/5,0) -> 0.4 | Q29: 46239 | R29: 46265 | U29: =MAX(IF(T29<>"",T29,R29)-TODAY(),0) -> 12
A30: 27 | B30: Umburanas 13 | C30: Jazida Santo Anjo | D30: 3.66 | F30: Concluído | G30: 46241 | H30: Não iniciado | J30: Não iniciado | L30: Não iniciado | M30: Não iniciado | N30: Equipe de Campo | O30: =IF(P30=0,"Não iniciado",IF(P30=1,"Concluído",IF(AND(TODAY()>IF(T30<>"",T30,R30),P30<1),"Atrasado","Em andamento"))) -> Em andamento | P30: =IFERROR((COUNTIF(F30,"Concluído")+COUNTIF(H30,"Concluído")+COUNTIF(J30,"Concluído")+COUNTIF(L30,"Concluído")+COUNTIF(M30,"Concluído"))/5,0) -> 0.2 | Q30: 46239 | R30: 46265 | U30: =MAX(IF(T30<>"",T30,R30)-TODAY(),0) -> 12
A31: 28 | B31: Umburanas 13 | C31: Jazida Santo Antonio | D31: 0.63 | F31: Concluído | G31: 46241 | H31: Não iniciado | J31: Não iniciado | L31: Não iniciado | M31: Não iniciado | N31: Equipe de Campo | O31: =IF(P31=0,"Não iniciado",IF(P31=1,"Concluído",IF(AND(TODAY()>IF(T31<>"",T31,R31),P31<1),"Atrasado","Em andamento"))) -> Em andamento | P31: =IFERROR((COUNTIF(F31,"Concluído")+COUNTIF(H31,"Concluído")+COUNTIF(J31,"Concluído")+COUNTIF(L31,"Concluído")+COUNTIF(M31,"Concluído"))/5,0) -> 0.2 | Q31: 46239 | R31: 46265 | U31: =MAX(IF(T31<>"",T31,R31)-TODAY(),0) -> 12
A32: 29 | B32: Umburanas 17 | C32: Jazido Campo Alegre | D32: 4.67 | F32: Concluído | G32: 46241 | H32: Não iniciado | J32: Não iniciado | L32: Não iniciado | M32: Não iniciado | N32: Equipe de Campo | O32: =IF(P32=0,"Não iniciado",IF(P32=1,"Concluído",IF(AND(TODAY()>IF(T32<>"",T32,R32),P32<1),"Atrasado","Em andamento"))) -> Em andamento | P32: =IFERROR((COUNTIF(F32,"Concluído")+COUNTIF(H32,"Concluído")+COUNTIF(J32,"Concluído")+COUNTIF(L32,"Concluído")+COUNTIF(M32,"Concluído"))/5,0) -> 0.2 | Q32: 46239 | R32: 46265 | U32: =MAX(IF(T32<>"",T32,R32)-TODAY(),0) -> 12
A33: 30 | B33: - | C33: Jazida do Meio | D33: 6.39 | E33: Manutenção média | F33: Concluído | G33: 46241 | H33: Não iniciado | J33: Não iniciado | L33: Não iniciado | M33: Não iniciado | N33: Equipe de Campo | O33: =IF(P33=0,"Não iniciado",IF(P33=1,"Concluído",IF(AND(TODAY()>IF(T33<>"",T33,R33),P33<1),"Atrasado","Em andamento"))) -> Em andamento | P33: =IFERROR((COUNTIF(F33,"Concluído")+COUNTIF(H33,"Concluído")+COUNTIF(J33,"Concluído")+COUNTIF(L33,"Concluído")+COUNTIF(M33,"Concluído"))/5,0) -> 0.2 | Q33: 46239 | R33: 46265 | U33: =MAX(IF(T33<>"",T33,R33)-TODAY(),0) -> 12
A34: 31 | B34: Umburanas 02 | C34: Bota-fora 08 | D34: 1.2982 | E34: Manutenção Basica | F34: Concluído | G34: 46241 | H34: Não iniciado | J34: Não iniciado | L34: Não iniciado | M34: Não iniciado | N34: Equipe de Campo | O34: =IF(P34=0,"Não iniciado",IF(P34=1,"Concluído",IF(AND(TODAY()>IF(T34<>"",T34,R34),P34<1),"Atrasado","Em andamento"))) -> Em andamento | P34: =IFERROR((COUNTIF(F34,"Concluído")+COUNTIF(H34,"Concluído")+COUNTIF(J34,"Concluído")+COUNTIF(L34,"Concluído")+COUNTIF(M34,"Concluído"))/5,0) -> 0.2 | Q34: 46239 | R34: 46265 | U34: =MAX(IF(T34<>"",T34,R34)-TODAY(),0) -> 12
A35: 32 | B35: Umburanas 09 | C35: Bota-fora 24 | D35: 0.7486 | F35: Concluído | G35: 46241 | H35: Não iniciado | J35: Não iniciado | L35: Não iniciado | M35: Não iniciado | N35: Equipe de Campo | O35: =IF(P35=0,"Não iniciado",IF(P35=1,"Concluído",IF(AND(TODAY()>IF(T35<>"",T35,R35),P35<1),"Atrasado","Em andamento"))) -> Em andamento | P35: =IFERROR((COUNTIF(F35,"Concluído")+COUNTIF(H35,"Concluído")+COUNTIF(J35,"Concluído")+COUNTIF(L35,"Concluído")+COUNTIF(M35,"Concluído"))/5,0) -> 0.2 | Q35: 46239 | R35: 46265 | U35: =MAX(IF(T35<>"",T35,R35)-TODAY(),0) -> 12
A36: 33 | B36: Umburanas 19 | C36: Bota-fora 04 | D36: 0.6484 | E36: Áreas consolidadas | F36: Não aplicável | H36: Não iniciado | J36: Não iniciado | L36: Não iniciado | M36: Não iniciado | N36: Equipe de Campo | O36: =IF(P36=0,"Não iniciado",IF(P36=1,"Concluído",IF(AND(TODAY()>IF(T36<>"",T36,R36),P36<1),"Atrasado","Em andamento"))) -> Não iniciado | P36: =IFERROR((COUNTIF(F36,"Concluído")+COUNTIF(H36,"Concluído")+COUNTIF(J36,"Concluído")+COUNTIF(L36,"Concluído")+COUNTIF(M36,"Concluído"))/5,0) -> 0 | Q36: 46239 | R36: 46265 | U36: =MAX(IF(T36<>"",T36,R36)-TODAY(),0) -> 12 | V36: Áreas Consolidadas
A37: 34 | B37: Umburanas 10 | C37: Caixa de empréstimo 14 | D37: 1.2756 | F37: Não aplicável | H37: Não iniciado | J37: Não iniciado | L37: Não iniciado | M37: Não iniciado | N37: Equipe de Campo | O37: =IF(P37=0,"Não iniciado",IF(P37=1,"Concluído",IF(AND(TODAY()>IF(T37<>"",T37,R37),P37<1),"Atrasado","Em andamento"))) -> Não iniciado | P37: =IFERROR((COUNTIF(F37,"Concluído")+COUNTIF(H37,"Concluído")+COUNTIF(J37,"Concluído")+COUNTIF(L37,"Concluído")+COUNTIF(M37,"Concluído"))/5,0) -> 0 | Q37: 46239 | R37: 46265 | U37: =MAX(IF(T37<>"",T37,R37)-TODAY(),0) -> 12 | V37: Áreas Consolidadas
A38: 35 | B38: Umburanas 23 | C38: Caixa de empréstimo 16 | D38: 0.3784 | F38: Não aplicável | H38: Não iniciado | J38: Não iniciado | L38: Não iniciado | M38: Não iniciado | N38: Equipe de Campo | O38: =IF(P38=0,"Não iniciado",IF(P38=1,"Concluído",IF(AND(TODAY()>IF(T38<>"",T38,R38),P38<1),"Atrasado","Em andamento"))) -> Não iniciado | P38: =IFERROR((COUNTIF(F38,"Concluído")+COUNTIF(H38,"Concluído")+COUNTIF(J38,"Concluído")+COUNTIF(L38,"Concluído")+COUNTIF(M38,"Concluído"))/5,0) -> 0 | Q38: 46239 | R38: 46265 | U38: =MAX(IF(T38<>"",T38,R38)-TODAY(),0) -> 12 | V38: Áreas Consolidadas
A39: 36 | B39: Umburanas 15 | C39: Canteiro de apoio 04 | D39: 0.3598 | F39: Não aplicável | H39: Não iniciado | J39: Não iniciado | L39: Não iniciado | M39: Não iniciado | N39: Equipe de Campo | O39: =IF(P39=0,"Não iniciado",IF(P39=1,"Concluído",IF(AND(TODAY()>IF(T39<>"",T39,R39),P39<1),"Atrasado","Em andamento"))) -> Não iniciado | P39: =IFERROR((COUNTIF(F39,"Concluído")+COUNTIF(H39,"Concluído")+COUNTIF(J39,"Concluído")+COUNTIF(L39,"Concluído")+COUNTIF(M39,"Concluído"))/5,0) -> 0 | Q39: 46239 | R39: 46265 | U39: =MAX(IF(T39<>"",T39,R39)-TODAY(),0) -> 12 | V39: Áreas Consolidadas
A40: 37 | B40: Umburanas 05 | C40: Bota-fora 22 | D40: 0.6392 | F40: Concluído | G40: 46241 | H40: Não iniciado | J40: Não iniciado | L40: Não iniciado | M40: Não iniciado | N40: Equipe de Campo | O40: =IF(P40=0,"Não iniciado",IF(P40=1,"Concluído",IF(AND(TODAY()>IF(T40<>"",T40,R40),P40<1),"Atrasado","Em andamento"))) -> Em andamento | P40: =IFERROR((COUNTIF(F40,"Concluído")+COUNTIF(H40,"Concluído")+COUNTIF(J40,"Concluído")+COUNTIF(L40,"Concluído")+COUNTIF(M40,"Concluído"))/5,0) -> 0.2 | Q40: 46239 | R40: 46265 | U40: =MAX(IF(T40<>"",T40,R40)-TODAY(),0) -> 12
A41: 38 | B41: Umburanas 05 | C41: Bota-fora 25 | D41: 0.7635 | E41: Áreas consolidadas | F41: Concluído | G41: 46241 | H41: Não iniciado | J41: Não iniciado | L41: Não iniciado | M41: Não iniciado | N41: Equipe de Campo | O41: =IF(P41=0,"Não iniciado",IF(P41=1,"Concluído",IF(AND(TODAY()>IF(T41<>"",T41,R41),P41<1),"Atrasado","Em andamento"))) -> Em andamento | P41: =IFERROR((COUNTIF(F41,"Concluído")+COUNTIF(H41,"Concluído")+COUNTIF(J41,"Concluído")+COUNTIF(L41,"Concluído")+COUNTIF(M41,"Concluído"))/5,0) -> 0.2 | Q41: 46239 | R41: 46265 | U41: =MAX(IF(T41<>"",T41,R41)-TODAY(),0) -> 12
A43: Indicador | B43: Valor | C43: Meta | D43: % | E43: Indicador | F43: Valor | G43: Meta | H43: %
A44: Áreas com coleta concluída | B44: 33 | C44: 38 | D44: =IFERROR(B44/C44,0) -> 0.86842105 | E44: Não iniciadas | F44: =COUNTIF(O4:O41,"Não iniciado") -> 5 | G44: 38 | H44: =IFERROR(F44/G44,0) -> 0.13157895
A45: Hectares com coleta concluída | B45: 41.87 | C45: 50.26 | D45: =IFERROR(B45/C45,0) -> 0.83306805 | E45: Em andamento | F45: 5 | G45: 38 | H45: =IFERROR(F45/G45,0) -> 0.13157895
A46: Áreas com manutenção concluída | B46: 1 | C46: 38 | D46: =IFERROR(B46/C46,0) -> 0.026315789 | E46: Concluídas | F46: 1 | G46: 38 | H46: =IFERROR(F46/G46,0) -> 0.026315789
A47: Áreas com irrigação concluída | B47: =COUNTIF(J4:J41,"Concluído") -> 0 | C47: 38 | D47: =IFERROR(B47/C47,0) -> 0 | E47: Atrasadas | F47: =COUNTIF(O4:O41,"Atrasado") -> 0 | G47: 38 | H47: =IFERROR(F47/G47,0) -> 0

Sheet Dashboard Executivo
A1: 10
A2: EcoBrasil Consultoria Ambiental | Atualização quinzenal | 38 áreas | 50,26 ha
B3: PROGRESSO GERAL | F3: ÁREAS CONCLUÍDAS | J3: HECTARES EXECUTADOS
B4: =IFERROR(AVERAGE(MIN(C16/Configurações!B4,1),MIN(H16/Configurações!B5,1)),0) -> 0.85074455 | F4: =MIN(C16,Configurações!B4) -> 33 | J4: =MIN(H16,Configurações!B5) -> 41.87
B7: ATIVIDADES CONCLUÍDAS | F7: PRAZO CONTRATUAL | J7: PRORROGAÇÕES
B8: =COUNTIF(Planejamento!J4:J7,"Concluído") -> 2 | F8: =MAX(Configurações!B8-Configurações!B10,0) -> 25 | J8: =COUNTIF(Planejamento!J4:J7,"Prorrogado")+COUNTIF(Planejamento!J4:J7,"Atrasado") -> 0
B12: BARRA DE PROGRESSO GERAL
B13: =B4 -> 0.85074455
A15: LANÇAMENTO RÁPIDO — PREENCHA SOMENTE AS CÉLULAS AMARELAS
A16: Áreas prontas | C16: 33 | D16: de 38 áreas | F16: Hectares executados | H16: 41.87 | I16: de 50,26 ha
A17: Áreas pendentes | C17: =MAX(Configurações!B4-C16,0) -> 5 | D17: Percentual das áreas | F17: =IFERROR(C16/Configurações!B4,0) -> 0.86842105 | G17: Hectares restantes | I17: =MAX(Configurações!B5-H16,0) -> 8.39
A18: Status | B18: Quantidade | D18: Atividade | E18: % | G18: Indicador | H18: Valor
A19: Não iniciado | B19: =COUNTIF(Planejamento!J4:J7,"Não iniciado") -> 0 | D19: Áreas concluídas | E19: =MIN(C16/Configurações!B4,1) -> 0.86842105 | G19: Executado | H19: =B4 -> 0.85074455
A20: Em andamento | B20: =COUNTIF(Planejamento!J4:J7,"Em andamento") -> 2 | D20: Avanço em hectares | E20: =MIN(H16/Configurações!B5,1) -> 0.83306805 | G20: Restante | H20: =1-H19 -> 0.14925545
A21: Concluído | B21: =COUNTIF(Planejamento!J4:J7,"Concluído") -> 2 | D21: Canteiro principal | E21: =Planejamento!K6 -> 1
A22: Prorrogado/Atrasado | B22: =COUNTIF(Planejamento!J4:J7,"Prorrogado")+COUNTIF(Planejamento!J4:J7,"Atrasado") -> 0 | D22: Sistema de irrigação | E22: =Planejamento!K7 -> 0
D41: Data | E41: Planejado | F41: Realizado | G41: Observação
D42: 46249 | E42: 0.5 | F42: =AVERAGE('Base Áreas'!G4:G22) -> 0.94736842 | G42: 1ª quinzena
D43: 46265 | E43: 1 | F43: =AVERAGE('Base Áreas'!G23:G41) -> 0.78947368 | G43: 2ª quinzena
D44: 46280 | E44: 1 | F44: =AVERAGE(Planejamento!K4:K6) -> 0.64575436 | G44: Prorrogação, se aplicável

Sheet Base Áreas
A1: CONTROLE DAS 38 ÁREAS — COLETA DE SOLO
A3: Área | B3: Área (ha) | C3: Data prevista | D3: Data realizada | E3: Responsável | F3: Status | G3: % Concluído | H3: Quinzena | I3: Resultado/Protocolo | J3: Pendência | K3: Observação | L3: Prorrogação
A4: Área 01 | B4: 1.18 | C4: 46249 | E4: Equipe de Campo | F4: Atrasado | G4: 0 | H4: 1ª quinzena
A5: Área 02 | B5: 1.52 | C5: 46249 | D5: 46241 | E5: Equipe de Campo | F5: Concluído | G5: 1 | H5: 1ª quinzena
A6: Área 03 | B6: 0.2 | C6: 46249 | D6: 46241 | E6: Equipe de Campo | F6: Concluído | G6: 1 | H6: 1ª quinzena
A7: Área 04 | B7: 1.95 | C7: 46249 | D7: 46241 | E7: Equipe de Campo | F7: Concluído | G7: 1 | H7: 1ª quinzena
A8: Área 05 | B8: 1.93 | C8: 46249 | D8: 46241 | E8: Equipe de Campo | F8: Concluído | G8: 1 | H8: 1ª quinzena
A9: Área 06 | B9: 1.04 | C9: 46249 | D9: 46241 | E9: Equipe de Campo | F9: Concluído | G9: 1 | H9: 1ª quinzena
A10: Área 07 | B10: 0.64 | C10: 46249 | D10: 46241 | E10: Equipe de Campo | F10: Concluído | G10: 1 | H10: 1ª quinzena
A11: Área 08 | B11: 1.55 | C11: 46249 | D11: 46241 | E11: Equipe de Campo | F11: Concluído | G11: 1 | H11: 1ª quinzena
A12: Área 09 | B12: 0.28 | C12: 46249 | D12: 46241 | E12: Equipe de Campo | F12: Concluído | G12: 1 | H12: 1ª quinzena
A13: Área 10 | B13: 1.79 | C13: 46249 | D13: 46241 | E13: Equipe de Campo | F13: Concluído | G13: 1 | H13: 1ª quinzena
A14: Área 11 | B14: 0.56 | C14: 46249 | D14: 46241 | E14: Equipe de Campo | F14: Concluído | G14: 1 | H14: 1ª quinzena
A15: Área 12 | B15: 1.29 | C15: 46249 | D15: 46241 | E15: Equipe de Campo | F15: Concluído | G15: 1 | H15: 1ª quinzena
A16: Área 13 | B16: 0.97 | C16: 46249 | D16: 46241 | E16: Equipe de Campo | F16: Concluído | G16: 1 | H16: 1ª quinzena
... A41: Área 38 | B41: 0.7635 | C41: 46265 | D41: 46241 | E41: Equipe de Campo | F41: Concluído | G41: 1 | H41: 2ª quinzena

Sheet Configurações
A1: CONFIGURAÇÕES DO PAINEL
A3: Parâmetro | B3: Valor | D3: Status | F3: Responsáveis
A4: Total de áreas | B4: 38 | D4: Não iniciado | E4: 5 | F4: Equipe de Campo
A5: Total previsto (ha) | B5: 50.26 | D5: Em andamento | F5: Equipe de Manutenção
A6: Canteiro principal (ha) | B6: 3.46 | D6: Concluído | E6: 33 | F6: Equipe de Irrigação
A7: Data-base | B7: 46239 | D7: Atrasado | F7: Gestão Técnica
A8: Fim contratual | B8: 46265 | D8: Prorrogado
A9: Periodicidade (dias) | B9: 15
A10: Data de atualização | B10: 46240
